11282017-054608.log

1) Telegram timeout (2x total)

2017-11-28 07:34:51,324 - INFO - Sending Telegram alert.
2017-11-28 07:34:51,325 - DEBUG - trade_message: Bought 0.1874 @ 0.0591
2017-11-28 07:34:56,330 - ERROR - Timed out
Traceback (most recent call last):
  File "/home/ec2-user/lorenzbot/env/local/lib/python3.6/site-packages/telegram/vendor/ptb_urllib3/urllib3/connectionpool.py", line 402, in _make_request
    six.raise_from(e, None)
  File "<string>", line 2, in raise_from
  File "/home/ec2-user/lorenzbot/env/local/lib/python3.6/site-packages/telegram/vendor/ptb_urllib3/urllib3/connectionpool.py", line 398, in _make_request
    httplib_response = conn.getresponse()
  File "/usr/lib64/python3.6/http/client.py", line 1331, in getresponse
    response.begin()
  File "/usr/lib64/python3.6/http/client.py", line 297, in begin
    version, status, reason = self._read_status()
  File "/usr/lib64/python3.6/http/client.py", line 258, in _read_status
    line = str(self.fp.readline(_MAXLINE + 1), "iso-8859-1")
  File "/usr/lib64/python3.6/socket.py", line 586, in readinto
    return self._sock.recv_into(b)
  File "/usr/lib64/python3.6/ssl.py", line 1002, in recv_into
    return self.read(nbytes, buffer)
  File "/usr/lib64/python3.6/ssl.py", line 865, in read
    return self._sslobj.read(len, buffer)
  File "/usr/lib64/python3.6/ssl.py", line 625, in read
    v = self._sslobj.read(len, buffer)
socket.timeout: The read operation timed out

During handling of the above exception, another exception occurred:

Traceback (most recent call last):
  File "/home/ec2-user/lorenzbot/env/local/lib/python3.6/site-packages/telegram/utils/request.py", line 190, in _request_wrapper
    resp = self._con_pool.request(*args, **kwargs)
  File "/home/ec2-user/lorenzbot/env/local/lib/python3.6/site-packages/telegram/vendor/ptb_urllib3/urllib3/request.py", line 70, in request
    **urlopen_kw)
  File "/home/ec2-user/lorenzbot/env/local/lib/python3.6/site-packages/telegram/vendor/ptb_urllib3/urllib3/request.py", line 148, in request_encode_body
    return self.urlopen(method, url, **extra_kw)
  File "/home/ec2-user/lorenzbot/env/local/lib/python3.6/site-packages/telegram/vendor/ptb_urllib3/urllib3/poolmanager.py", line 244, in urlopen
    response = conn.urlopen(method, u.request_uri, **kw)
  File "/home/ec2-user/lorenzbot/env/local/lib/python3.6/site-packages/telegram/vendor/ptb_urllib3/urllib3/connectionpool.py", line 666, in urlopen
    _stacktrace=sys.exc_info()[2])
  File "/home/ec2-user/lorenzbot/env/local/lib/python3.6/site-packages/telegram/vendor/ptb_urllib3/urllib3/util/retry.py", line 347, in increment
    raise six.reraise(type(error), error, _stacktrace)
  File "/home/ec2-user/lorenzbot/env/local/lib/python3.6/site-packages/telegram/vendor/ptb_urllib3/urllib3/packages/six.py", line 686, in reraise
    raise value
  File "/home/ec2-user/lorenzbot/env/local/lib/python3.6/site-packages/telegram/vendor/ptb_urllib3/urllib3/connectionpool.py", line 617, in urlopen
    chunked=chunked)
  File "/home/ec2-user/lorenzbot/env/local/lib/python3.6/site-packages/telegram/vendor/ptb_urllib3/urllib3/connectionpool.py", line 405, in _make_request
    exc_cls=ReadTimeoutError)
  File "/home/ec2-user/lorenzbot/env/local/lib/python3.6/site-packages/telegram/vendor/ptb_urllib3/urllib3/connectionpool.py", line 321, in _raise_timeout
    raise exc_cls(*args)
telegram.vendor.ptb_urllib3.urllib3.exceptions.ReadTimeoutError: HTTPSConnectionPool(host='api.telegram.org', port=443): Read timed out. (read timeout=5.0)

During handling of the above exception, another exception occurred:

Traceback (most recent call last):
  File "lorenzbot.py", line 1058, in <module>
    exec_trade('buy', base_price_target, buy_amount_current)
  File "lorenzbot.py", line 418, in exec_trade
    telegram_send_message(updater.bot, telegram_message)
  File "lorenzbot.py", line 647, in telegram_send_message
    bot.send_message(chat_id=user, text=trade_message)
  File "/home/ec2-user/lorenzbot/env/local/lib/python3.6/site-packages/telegram/bot.py", line 57, in decorator
    result = func(self, *args, **kwargs)
  File "/home/ec2-user/lorenzbot/env/local/lib/python3.6/site-packages/telegram/bot.py", line 82, in decorator
    result = self._request.post(url, data, timeout=kwargs.get('timeout'))
  File "/home/ec2-user/lorenzbot/env/local/lib/python3.6/site-packages/telegram/utils/request.py", line 272, in post
    **urlopen_kwargs)
  File "/home/ec2-user/lorenzbot/env/local/lib/python3.6/site-packages/telegram/utils/request.py", line 192, in _request_wrapper
    raise TimedOut()
telegram.error.TimedOut: Timed out

----

2) Error when placing new entry buy after sell

2017-11-28 10:02:41,379 - DEBUG - [SELL] mongo_response: <pymongo.results.InsertOneResult object at 0x7f4d9c1609c8>
2017-11-28 10:02:41,379 - INFO - Sell logged to MongoDB database collection 11282017_054609
2017-11-28 10:02:41,394 - INFO - Created new collection: 11282017_100241
2017-11-28 10:02:41,394 - DEBUG - Sell completely filled. New collection starting empty.
2017-11-28 10:02:41,394 - DEBUG - Entering base_price calculation.
2017-11-28 10:02:41,395 - DEBUG - db[coll_current].count(): 0
2017-11-28 10:02:41,395 - INFO - No trade log found. Making entry buy.
2017-11-28 10:02:41,395 - DEBUG - trade_amount[CALC]: 0.00
2017-11-28 10:02:41,488 - DEBUG - Regular lookup (price) in calc_limit_price().
2017-11-28 10:02:41,488 - DEBUG - actual: 0.06365000
2017-11-28 10:02:41,488 - DEBUG - book_tot: 773.10
2017-11-28 10:02:41,488 - DEBUG - actual: 0.06365000
2017-11-28 10:02:41,488 - DEBUG - book_tot: 773.10
2017-11-28 10:02:41,488 - DEBUG - calc_limit_price() successful within limits (depth=40).
2017-11-28 10:02:41,488 - DEBUG - trade_price_initial[CALC]: 0.06
2017-11-28 10:02:41,488 - INFO - Entry trade amount: 0.0007
2017-11-28 10:02:41,489 - DEBUG - trade_price_initial: 0.06365000
2017-11-28 10:02:41,659 - ERROR - Entry buy failed. Exiting.
Traceback (most recent call last):
  File "lorenzbot.py", line 183, in calc_base
    exec_trade('buy', trade_price_initial, trade_amount)
  File "lorenzbot.py", line 336, in exec_trade
    trade_response = polo.buy('USDT_STR', limit, amount, 'immediateOrCancel')
  File "/home/ec2-user/lorenzbot/env/local/lib/python3.6/site-packages/poloniex/__init__.py", line 430, in buy
    return self.__call__('buy', args)
  File "/home/ec2-user/lorenzbot/env/local/lib/python3.6/site-packages/poloniex/__init__.py", line 143, in retrying
    return func(*args, **kwargs)
  File "/home/ec2-user/lorenzbot/env/local/lib/python3.6/site-packages/poloniex/__init__.py", line 203, in __call__
    return self.handleReturned(ret.text)
  File "/home/ec2-user/lorenzbot/env/local/lib/python3.6/site-packages/poloniex/__init__.py", line 270, in handleReturned
    raise PoloniexError(out['error'])
poloniex.PoloniexError: Total must be at least 0.0001.

----

3) Program running --> Withdrew STR --> (STR balance < Total bought)

(env) [ec2-user@ip-172-31-54-26 lorenzbot]$ python lorenzbot.py --dynamicamount -m 270 -l 30 --dynamicloop --live --telegram
2017-11-29 23:34:15,486 - INFO - MongoDB running.
2017-11-29 23:34:15,488 - INFO - Using default MongoDB database "lorenzbot".
2017-11-29 23:34:15,488 - WARNING - Total USDT trade amount is set to $270.00.
Is this correct? (y/n): y
2017-11-29 23:34:16,500 - INFO - USDT trade amount confirmed.
2017-11-29 23:34:16,500 - INFO - Dynamic trade amount calculation activated.
2017-11-29 23:34:16,500 - INFO - Dynamic loop time calculation activated. Base loop time set to 30 seconds.
2017-11-29 23:34:16,500 - INFO - CSV logging activated.
2017-11-29 23:34:16,500 - INFO - Telegram logging active. Send "/connect" to @lorenzbot_bot to receive alerts.
2017-11-29 23:34:16,502 - INFO - Found existing collection: 11292017_230456
2017-11-29 23:34:16,502 - INFO - Found Telegram config file.
2017-11-29 23:34:16,503 - INFO - Found Poloniex config file.
2017-11-29 23:34:16,504 - WARNING - Live trading ENABLED.
2017-11-29 23:34:16,814 - INFO - Current Maker Fee: 0.1500%
2017-11-29 23:34:16,814 - INFO - Current Taker Fee: 0.2500%
2017-11-29 23:34:16,818 - INFO - Base Price: 0.075486
2017-11-29 23:34:17,003 - INFO - Balance STR:  3584.3527
2017-11-29 23:34:17,003 - INFO - Balance USDT: 1.8778
2017-11-29 23:34:17,004 - INFO - Total STR Bought: 2464.3527
2017-11-29 23:34:17,005 - INFO - Total USDT Spent: 186.0247
2017-11-29 23:34:17,006 - INFO - Total Buy Count: 1
2017-11-29 23:34:17,007 - INFO - Avg. Trade Amount: 2464.3527
2017-11-29 23:34:17,008 - WARNING - USDT balance less than remaining USDT amount allotted for trading. Adjusting allotment to available balance.
2017-11-29 23:34:17,010 - INFO - Remaining Tradable USDT Balance Adjusted: -1.8802
2017-11-29 23:34:17,010 - INFO - Tradable USDT Remaining: -1.8802
2017-11-29 23:34:17,077 - WARNING - Volume not satisfied at default order book depth=40. Retrying with depth = 80.
2017-11-29 23:34:18,145 - WARNING - Volume not satisfied at default order book depth=80. Retrying with depth = 120.
2017-11-29 23:34:19,221 - WARNING - Volume not satisfied at default order book depth=120. Retrying with depth = 160.
^CTraceback (most recent call last):
  File "lorenzbot.py", line 1121, in <module>
    verify_initial = verify_amounts()
  File "lorenzbot.py", line 895, in verify_amounts
    buy_amount_max = calc_limit_price(trade_usdt_remaining, 'buy', reverseLookup=True, withFees=True)
  File "lorenzbot.py", line 327, in calc_limit_price
    time.sleep(1)
KeyboardInterrupt
^CException ignored in: <module 'threading' from '/usr/lib64/python3.6/threading.py'>
Traceback (most recent call last):
  File "/usr/lib64/python3.6/threading.py", line 1294, in _shutdown
    t.join()
  File "/usr/lib64/python3.6/threading.py", line 1056, in join
    self._wait_for_tstate_lock()
  File "/usr/lib64/python3.6/threading.py", line 1072, in _wait_for_tstate_lock
    elif lock.acquire(block, timeout):
KeyboardInterrupt

----

4) Telegram error after startup, resume of previous trade cycle, buy, attempt to send buy alert

2017-11-30 01:49:09,388 - INFO - TRADE CONDITIONS MET --> BUYING
2017-11-30 01:49:09,855 - INFO - Buy logged to MongoDB database collection 11292017_042028
2017-11-30 01:49:09,872 - INFO - Logging trade details to csv file.
2017-11-30 01:49:09,872 - INFO - No users connected to Telegram. Skipping alert.
2017-11-30 01:49:09,873 - INFO - Price Difference from Base: -10.9125%
2017-11-30 01:49:09,873 - INFO - Trade loop complete. Sleeping for 27.38 seconds.
2017-11-30 01:49:09,873 - INFO - ----[LOOP END]----
Exception in thread updater:
Traceback (most recent call last):
  File "/home/ec2-user/lorenzbot/env/local/lib/python3.6/site-packages/telegram/vendor/ptb_urllib3/urllib3/connectionpool.py", line 402, in _make_request
    six.raise_from(e, None)
  File "<string>", line 2, in raise_from
  File "/home/ec2-user/lorenzbot/env/local/lib/python3.6/site-packages/telegram/vendor/ptb_urllib3/urllib3/connectionpool.py", line 398, in _make_request
    httplib_response = conn.getresponse()
  File "/usr/lib64/python3.6/http/client.py", line 1331, in getresponse
    response.begin()
  File "/usr/lib64/python3.6/http/client.py", line 297, in begin
    version, status, reason = self._read_status()
  File "/usr/lib64/python3.6/http/client.py", line 258, in _read_status
    line = str(self.fp.readline(_MAXLINE + 1), "iso-8859-1")
  File "/usr/lib64/python3.6/socket.py", line 586, in readinto
    return self._sock.recv_into(b)
  File "/usr/lib64/python3.6/ssl.py", line 1002, in recv_into
    return self.read(nbytes, buffer)
  File "/usr/lib64/python3.6/ssl.py", line 865, in read
    return self._sslobj.read(len, buffer)
  File "/usr/lib64/python3.6/ssl.py", line 625, in read
    v = self._sslobj.read(len, buffer)
socket.timeout: The read operation timed out

During handling of the above exception, another exception occurred:

Traceback (most recent call last):
  File "/home/ec2-user/lorenzbot/env/local/lib/python3.6/site-packages/telegram/utils/request.py", line 190, in _request_wrapper
    resp = self._con_pool.request(*args, **kwargs)
  File "/home/ec2-user/lorenzbot/env/local/lib/python3.6/site-packages/telegram/vendor/ptb_urllib3/urllib3/request.py", line 70, in request
    **urlopen_kw)
  File "/home/ec2-user/lorenzbot/env/local/lib/python3.6/site-packages/telegram/vendor/ptb_urllib3/urllib3/request.py", line 148, in request_encode_body
    return self.urlopen(method, url, **extra_kw)
  File "/home/ec2-user/lorenzbot/env/local/lib/python3.6/site-packages/telegram/vendor/ptb_urllib3/urllib3/poolmanager.py", line 244, in urlopen
    response = conn.urlopen(method, u.request_uri, **kw)
  File "/home/ec2-user/lorenzbot/env/local/lib/python3.6/site-packages/telegram/vendor/ptb_urllib3/urllib3/connectionpool.py", line 666, in urlopen
    _stacktrace=sys.exc_info()[2])
  File "/home/ec2-user/lorenzbot/env/local/lib/python3.6/site-packages/telegram/vendor/ptb_urllib3/urllib3/util/retry.py", line 347, in increment
    raise six.reraise(type(error), error, _stacktrace)
  File "/home/ec2-user/lorenzbot/env/local/lib/python3.6/site-packages/telegram/vendor/ptb_urllib3/urllib3/packages/six.py", line 686, in reraise
    raise value
  File "/home/ec2-user/lorenzbot/env/local/lib/python3.6/site-packages/telegram/vendor/ptb_urllib3/urllib3/connectionpool.py", line 617, in urlopen
    chunked=chunked)
  File "/home/ec2-user/lorenzbot/env/local/lib/python3.6/site-packages/telegram/vendor/ptb_urllib3/urllib3/connectionpool.py", line 405, in _make_request
    exc_cls=ReadTimeoutError)
  File "/home/ec2-user/lorenzbot/env/local/lib/python3.6/site-packages/telegram/vendor/ptb_urllib3/urllib3/connectionpool.py", line 321, in _raise_timeout
    raise exc_cls(*args)
telegram.vendor.ptb_urllib3.urllib3.exceptions.ReadTimeoutError: HTTPSConnectionPool(host='api.telegram.org', port=443): Read timed out. (read timeout=5.0)

During handling of the above exception, another exception occurred:

Traceback (most recent call last):
  File "/usr/lib64/python3.6/threading.py", line 916, in _bootstrap_inner
    self.run()
  File "/usr/lib64/python3.6/threading.py", line 864, in run
    self._target(*self._args, **self._kwargs)
  File "/home/ec2-user/lorenzbot/env/local/lib/python3.6/site-packages/telegram/ext/updater.py", line 149, in _thread_wrapper
    target(*args, **kwargs)
  File "/home/ec2-user/lorenzbot/env/local/lib/python3.6/site-packages/telegram/ext/updater.py", line 275, in _start_polling
    self._bootstrap(bootstrap_retries, clean=clean, webhook_url='', allowed_updates=None)
  File "/home/ec2-user/lorenzbot/env/local/lib/python3.6/site-packages/telegram/ext/updater.py", line 387, in _bootstrap
    url=webhook_url, certificate=cert, allowed_updates=allowed_updates)
  File "/home/ec2-user/lorenzbot/env/local/lib/python3.6/site-packages/telegram/bot.py", line 57, in decorator
    result = func(self, *args, **kwargs)
  File "/home/ec2-user/lorenzbot/env/local/lib/python3.6/site-packages/telegram/bot.py", line 1765, in set_webhook
    result = self._request.post(url_, data, timeout=timeout)
  File "/home/ec2-user/lorenzbot/env/local/lib/python3.6/site-packages/telegram/utils/request.py", line 272, in post
    **urlopen_kwargs)
  File "/home/ec2-user/lorenzbot/env/local/lib/python3.6/site-packages/telegram/utils/request.py", line 192, in _request_wrapper
    raise TimedOut()
telegram.error.TimedOut: Timed out